Workbook

Sheet Takeoff
A1: D01
A2: 2026-10-13
A6: Item | B6: Description | C6: Drawing | D6: Page | E6: Type | F6: Quantity | G6: Unit | H6: Rate | I6: Amount | J6: Notes
A7: 1 | B7: Door Leaf | C7: ARAK-P1R1-INB-SD-ID-RES-ZZZ-3320277-02.pdf | I7: =SUM(I8:I9) | K7: 1
A8: 1.1 | B8: Door Leaf | C8: ARAK-P1R1-INB-SD-ID-RES-ZZZ-3320277-02.pdf | D8: 1 | E8: Polygon | F8: 2.047494 | G8: sq m | H8: 0 | I8: =F8*H8
A9: 1.2 | B9: Door Leaf | C9: ARAK-P1R1-INB-SD-ID-RES-ZZZ-3320277-02.pdf | D9: 1 | E9: Polygon | F9: 4.0849 | G9: sq m | H9: 0 | I9: =F9*H9 | J9: 2.0424 sq m × 2
A10: 2 | B10: DOOR Architrave | C10: ARAK-P1R1-INB-SD-ID-RES-ZZZ-3320277-02.pdf | I10: =SUM(I11:I14) | K10: 1
A11: 2.1 | B11: DOOR Architrave | C11: ARAK-P1R1-INB-SD-ID-RES-ZZZ-3320277-02.pdf | D11: 1 | E11: Polygon | F11: 2.0533387 | G11: sq m | H11: 0 | I11: =F11*H11
A12: 2.2 | B12: DOOR Architrave 2 | C12: ARAK-P1R1-INB-SD-ID-RES-ZZZ-3320277-02.pdf | D12: 1 | E12: Polygon | F12: 2.0523932 | G12: sq m | H12: 0 | I12: =F12*H12
A13: 2.3 | B13: DOOR Architrave 3 | C13: ARAK-P1R1-INB-SD-ID-RES-ZZZ-3320277-02.pdf | D13: 1 | E13: Polygon | F13: 0.31648306 | G13: sq m | H13: 0 | I13: =F13*H13
A14: 2.4 | B14: DOOR Architrave 4 | C14: ARAK-P1R1-INB-SD-ID-RES-ZZZ-3320277-02.pdf | D14: 1 | E14: Polygon | F14: 0.33412734 | G14: sq m | H14: 0 | I14: =F14*H14
A15: 3 | B15: DOOR Architrave | C15: ARAK-P1R1-INB-SD-ID-RES-ZZZ-3320361-01.pdf | I15: 0 | K15: 1
A16: 4 | B16: Door Frame | C16: ARAK-P1R1-INB-SD-ID-RES-ZZZ-3320361-01.pdf | I16: =SUM(I17:I17) | K16: 1
A17: 4.1 | B17: Door Frame | C17: ARAK-P1R1-INB-SD-ID-RES-ZZZ-3320361-01.pdf | D17: 1 | E17: Polygon | F17: 0.0083957392 | G17: sq m | H17: 0 | I17: =F17*H17
A18: 5 | B18: Door Frame | C18: ARAK-P1R1-INB-SD-ID-RES-ZZZ-3320277-02.pdf | I18: =SUM(I19:I21) | K18: 1
A19: 5.1 | B19: Door Frame 1 | C19: ARAK-P1R1-INB-SD-ID-RES-ZZZ-3320277-02.pdf | D19: 1 | E19: Length | F19: 5.3324 | G19: m | H19: 0 | I19: =F19*H19
A20: 5.2 | B20: Door Frame 2 | C20: ARAK-P1R1-INB-SD-ID-RES-ZZZ-3320277-02.pdf | D20: 1 | E20: Length | F20: 2.1992 | G20: m | H20: 0 | I20: =F20*H20
A21: 5.3 | B21: Door Frame 3 | C21: ARAK-P1R1-INB-SD-ID-RES-ZZZ-3320277-02.pdf | D21: 1 | E21: Length | F21: 0.2666 | G21: m | H21: 0 | I21: =F21*H21
H23: Subtotal | I23: =SUMIF(K7:K21,1,I7:I21)
H24: VAT 5% | I24: =I23*5/100
H25: Total | I25: =I23+I24
A27: Prepared with Foldrule · 2026-10-14

Sheet Bill of Quantities
A1: RAK Doors — Bill of Quantities
A2: 2026-10-13
A3: Sections follow the Principles of Measurement (International). Quantities are given to the nearest whole unit (tonnes to two decimal places); measured figures are on the Takeoff sheet.
A5: Item | B5: Description | C5: Quantity | D5: Unit | E5: Rate | F5: Amount
A6: F | B6: WOODWORK
A7: A | B7: Door Leaf | C7: 6 | D7: m² | E7: 0 | F7: =C7*E7
A8: B | B8: Door Frame | C8: 1 | D8: m² | E8: 0 | F8: =C8*E8
A9: C | B9: Door Frame | C9: 8 | D9: m | E9: 0 | F9: =C9*E9
E10: To summary | F10: =SUM(F7:F9)
A12: H | B12: DOORS AND WINDOWS
A13: A | B13: DOOR Architrave | C13: 5 | D13: m² | E13: 0 | F13: =C13*E13
A14: B | B14: DOOR Architrave | C14: 5 | D14: m² | E14: 0 | F14: =C14*E14
E15: To summary | F15: =SUM(F13:F14)
B17: SUMMARY
B18: F Woodwork | F18: =F10
B19: H Doors and windows | F19: =F15
E20: Subtotal | F20: =SUM(F18:F19)
E21: VAT 5% | F21: =F20*5/100
E22: Total | F22: =F20+F21

Sheet Estimate summary
A1: RAK Doors — Estimate summary
A2: From the measured work to the tender sum, in AED. Amounts as at export; the bill sheets hold the detail.
B4: % | C4: Amount | D4: Note
A5: Measured work | C5: 0 | D5: Quantity × rate, from the takeoff
A6: Preliminaries | B6: 0 | C6: 0 | D6: Site setup, supervision, temporary works, insurances
A7: Provisional sums | C7: 0 | D7: Allowances for work not yet designed
A8: Works cost | C8: 0
A9: Contingency | B9: 0 | C9: 0 | D9: Risk allowance, on the works cost
A10: Overheads | B10: 0 | C10: 0 | D10: Head-office cost
A11: Profit | B11: 0 | C11: 0
A12: Tender sum (before VAT) | C12: 0
A13: VAT | B13: 0.05 | C13: 0
A14: Total | C14: 0

Sheet Materials to order
A1: RAK Doors — Materials to order
A2: Net quantity from the bill, plus waste, converted to the unit each material is bought in. Whole packs are rounded up. Material cost only: no labour or equipment.
A4: Code | B4: Material | C4: Net quantity | D4: Unit | E4: Waste | F4: Order | G4: Buy by | H4: One covers | I4: Price each | J4: Cost | K4: Supplier
A5: 06 00 00 | B5: 12mmThk plain MDF | C5: 2.05 | D5: m2 | E5: 0 | F5: 2.05 | G5: m2 | I5: 0 | J5: =F5*I5 -> 0
A6: 06 00 01 | B6: FR60mins Doorcore | C6: 2.05 | D6: m² | E6: 0 | F6: 2.05 | G6: m² | I6: 0 | J6: =F6*I6 -> 0
A7: 06 00 00 | B7: Solid Wood | C7: 0.01 | D7: m² | E7: 0 | F7: 0.01 | G7: m² | I7: 0 | J7: =F7*I7 -> 0
A8: 06 00 00 | B8: Solid Wood | C8: 5.33 | D8: m | E8: 0 | F8: 5.33 | G8: m | I8: 0 | J8: =F8*I8 -> 0
A9: 06 00 00 | B9: Timber | C9: 0.32 | D9: m² | E9: 0 | F9: 0.32 | G9: m² | I9: 0 | J9: =F9*I9 -> 0
A10: 06 00 00 | B10: Wrapping Veneer WD002 | C10: 8.94 | D10: m2 | E10: 0 | F10: 8.94 | G10: m2 | I10: 0 | J10: =F10*I10 -> 0
B11: Materials to buy | J11: =SUM(J5:J10)

Sheet Change log
A1: RAK Doors — Change log
A2: Every change to a quantity, rate, material, price or estimate setting, newest first.
A4: When | B4: Who | C4: What | D4: Item | E4: From | F4: To
A5: 46309.211 | B5: munsif | C5: material | D5: Door Frame 3 | E5: Solid Wood | F5: Wrapping Veneer WD002
A6: 46309.211 | B6: munsif | C6: added | D6: DOOR Architrave | F6: group
A7: 46309.211 | B7: munsif | C7: added | D7: Door Frame 3 | F7: 0.267 m
A8: 46309.211 | B8: munsif | C8: added | D8: DOOR Architrave | F8: group
A9: 46309.211 | B9: munsif | C9: material | D9: Door Frame 2 | E9: Solid Wood | F9: Wrapping Veneer WD002
A10: 46309.211 | B10: munsif | C10: added | D10: DOOR Architrave | F10: group
A11: 46309.211 | B11: munsif | C11: added | D11: DOOR Architrave | F11: group
A12: 46309.211 | B12: munsif | C12: added | D12: Door Frame 2 | F12: 2.199 m
A13: 46309.211 | B13: munsif | C13: added | D13: DOOR Architrave | F13: group
A14: 46309.211 | B14: munsif | C14: removed | D14: Door Frame 2 | E14: 0.505 sq m
A15: 46309.211 | B15: munsif | C15: added | D15: DOOR Architrave | F15: group
A16: 46309.21 | B16: munsif | C16: added | D16: DOOR Architrave | F16: group
A17: 46309.21 | B17: munsif | C17: quantity | D17: Door Frame 2 | E17: 0.471 sq m | F17: 0.505 sq m
A18: 46309.21 | B18: munsif | C18: added | D18: DOOR Architrave | F18: group
A19: 46309.21 | B19: munsif | C19: name | D19: Door Frame 2 | E19: New Area | F19: Door Frame 2
A20: 46309.21 | B20: munsif | C20: material | D20: Door Frame 2 | E20: none | F20: Wrapping Veneer WD002
A21: 46309.21 | B21: munsif | C21: added | D21: DOOR Architrave | F21: group
A22: 46309.209 | B22: munsif | C22: added | D22: New Area | F22: 0.471 sq m
A23: 46309.209 | B23: munsif | C23: added | D23: DOOR Architrave | F23: group
A24: 46309.209 | B24: munsif | C24: added | D24: DOOR Architrave | F24: group
A25: 46309.208 | B25: munsif | C25: material | D25: Door Frame 1 | E25: none | F25: Solid Wood
A26: 46309.208 | B26: munsif | C26: added | D26: DOOR Architrave | F26: group
A27: 46309.208 | B27: munsif | C27: added | D27: Door Frame 1 | F27: 5.332 m
A28: 46309.208 | B28: munsif | C28: added | D28: DOOR Architrave | F28: group
A29: 46309.208 | B29: munsif | C29: added | D29: Door Frame | F29: group
A30: 46309.208 | B30: munsif | C30: added | D30: DOOR Architrave | F30: group
A31: 46309.204 | B31: munsif | C31: removed | D31: Door Frame copy 1 | E31: 0.008 sq m
A32: 46309.204 | B32: munsif | C32: removed | D32: Door Frame copy | E32: group
A33: 46309.204 | B33: munsif | C33: added | D33: DOOR Architrave | F33: group
A34: 46309.204 | B34: munsif | C34: added | D34: Door Frame copy 1 | F34: 0.008 sq m
A35: 46309.204 | B35: munsif | C35: added | D35: Door Frame copy | F35: group
A36: 46309.204 | B36: munsif | C36: added | D36: DOOR Architrave | F36: group
A37: 46309.204 | B37: munsif | C37: name | D37: Door Frame | E37: Door Frame 1 | F37: Door Frame
A38: 46309.204 | B38: munsif | C38: added | D38: DOOR Architrave | F38: group
A39: 46309.203 | B39: munsif | C39: removed | D39: Door Frame 1 | E39: 0.482 m
A40: 46309.203 | B40: munsif | C40: removed | D40: Door Frame | E40: group
A41: 46309.203 | B41: munsif | C41: added | D41: DOOR Architrave | F41: group
...

Sheet Summary
B2: BILL OF QUANTITIES · KITCHEN FITOUT · TYPE N/A
B3: RAK Doors · ·
B5: PROJECT INFORMATION
B6: Main Contractor | C6: N/A
B7: Design Consultant | C7: N/A
B8: Supervision | C8: N/A
B9: Kitchen Type | C9: N/A
B10: Total Units | C10: 1
B11: Date | C11: 2026-10-13
B12: Revision | C12: N/A
B13: Currency / VAT | C13: AED (VAT 5%)
B15: DRAWING REFERENCES
B16: Ref 01 | C16: —
B18: SECTION SUMMARY
B19: Section | C19: Reference | D19: Description | E19: Items
B20: A | C20: — | D20: — | E20: 5
A23: All quantities subject to field verification. Unit rates to be inserted by tendering contractor.

Sheet BOQ_Matrix
A1: D01 (TYPE N/A) · RAK Doors · ·
H2: 1
B3: A | C3: SECTION
B4: S.No | C4: Description | D4: Unit | E4: Times | F4: L | G4: W | H4: H | I4: Total QTY | J4: Timber | K4: Solid Wood | L4: Wrapping Veneer WD002 | M4: FR60mins Doorcore | N4: Solid Wood | O4: 12mmThk plain MDF | P4: Remarks
C5: Door Leaf | F5: — | G5: — | H5: —
B6: A1 | C6: Door Leaf | D6: sq m | I6: =IF(E6<>"",E6,1) | M6: =I6
B7: A2 | C7: Door Leaf | D7: sq m | I7: =IF(E7<>"",E7,1) | L7: =I7 | P7: 2.0424 sq m × 2
C8: DOOR Architrave | F8: — | G8: — | H8: —
B9: B1 | C9: DOOR Architrave | D9: sq m | I9: =IF(E9<>"",E9,1) | O9: =I9
B10: B2 | C10: DOOR Architrave 2 | D10: sq m | I10: =IF(E10<>"",E10,1) | L10: =I10
B11: B3 | C11: DOOR Architrave 3 | D11: sq m | I11: =IF(E11<>"",E11,1) | J11: =I11
B12: B4 | C12: DOOR Architrave 4 | D12: sq m | I12: =IF(E12<>"",E12,1) | L12: =I12
C13: DOOR Architrave | F13: — | G13: — | H13: —
B14: C1 | C14: DOOR Architrave | D14: sq m | I14: =IF(E14<>"",E14,1) | O14: =I14
B15: C2 | C15: DOOR Architrave 2 | D15: sq m | I15: =IF(E15<>"",E15,1) | L15: =I15
B16: C3 | C16: DOOR Architrave 3 | D16: sq m | I16: =IF(E16<>"",E16,1) | J16: =I16
B17: C4 | C17: DOOR Architrave 4 | D17: sq m | I17: =IF(E17<>"",E17,1) | L17: =I17
C18: Door Frame | F18: — | G18: — | H18: —
B19: D1 | C19: Door Frame | D19: sq m | I19: =IF(E19<>"",E19,1) | K19: =I19
C20: Door Frame | F20: — | G20: — | H20: —
B21: E1 | C21: Door Frame 1 | D21: m | I21: =IF(E21<>"",E21,0) | N21: =I21
B22: E2 | C22: Door Frame 2 | D22: m | I22: =IF(E22<>"",E22,0) | L22: =I22
B23: E3 | C23: Door Frame 3 | D23: m | I23: =IF(E23<>"",E23,0) | L23: =I23
I24: Per Unit | J24: =SUM(J5:J23) | K24: =SUM(K5:K23) | L24: =SUM(L5:L23) | M24: =SUM(M5:M23) | N24: =SUM(N5:N23) | O24: =SUM(O5:O23)
H25: =H2 | I25: Total Unit | J25: =J24*H2/2.88 | K25: =K24*H2/2.88 | L25: =L24*H2/2.88 | M25: =M24*H2/2.88 | N25: =N24*H2/2.88 | O25: =O24*H2/2.88
A30: PROJECT TOTALS — All Sections
I31: Total QTY | J31: =J25 | K31: =K25 | L31: =L25 | M31: =M25 | N31: =N25 | O31: =O25
J32: Timber | K32: Solid Wood | L32: Wrapping Veneer WD002 | M32: FR60mins Doorcore | N32: Solid Wood | O32: 12mmThk plain MDF

Sheet Materials_List
B2: MATERIALS LIST · PROJECT TOTAL QUANTITIES
B3: RAK Doors · · TYPE N/A · 0 Units
B5: ★ All quantities are live-linked from BOQ_Matrix row 31. Edit dimensions in BOQ_Matrix; this sheet updates automatically.
B7: # | C7: Material ID | D7: Description / Specification | E7: Unit | F7: Total Quantity | G7: Sheet Size (m²) | H7: Sheets Needed | I7: Remarks
B8: 1 | C8: 63982919-372c-48ff-ade1-eef50fd85f27 | D8: Timber | E8: M² | F8: =BOQ_Matrix!J31 | G8: 2.88 | H8: =IFERROR(CEILING(F8/G8,1), "") | I8: Per m² supplied
B9: 2 | C9: d0256c18-4c77-4842-9e55-7c003d10bc7d | D9: Solid Wood | E9: M² | F9: =BOQ_Matrix!K31 | G9: 2.88 | H9: =IFERROR(CEILING(F9/G9,1), "") | I9: Per m² supplied
B10: 3 | C10: 25480b7c-4cf5-4d27-a8bd-8367a66eed99 | D10: Wrapping Veneer WD002 | E10: M² | F10: =BOQ_Matrix!L31 | G10: 2.88 | H10: =IFERROR(CEILING(F10/G10,1), "") | I10: Per m2 supplied
B11: 4 | C11: eed71fda-51a3-443f-ba35-fcf34da764b4 | D11: FR60mins Doorcore | E11: M² | F11: =BOQ_Matrix!M31 | G11: 2.88 | H11: =IFERROR(CEILING(F11/G11,1), "") | I11: Per m² supplied
B12: 5 | C12: 4f50dbef-3b3d-4a36-996e-372a3728716d | D12: Solid Wood | E12: M² | F12: =BOQ_Matrix!N31 | G12: 2.88 | H12: =IFERROR(CEILING(F12/G12,1), "") | I12: Per m supplied
B13: 6 | C13: a723fd95-ccea-465f-9f6a-1fbc1ab60d92 | D13: 12mmThk plain MDF | E13: M² | F13: =BOQ_Matrix!O31 | G13: 2.88 | H13: =IFERROR(CEILING(F13/G13,1), "") | I13: Per m2 supplied
B15: Sheet size basis: 2.88 m² per board · Sheets Needed rounds UP to whole boards · Count/Linear/Volume items show actual quantities.

Sheet Cost_Breakdown
B2: COST BREAKDOWN · MATERIAL QUANTITIES × UNIT RATES
B3: RAK Doors · · TYPE N/A · 1 Units · Currency: AED · VAT: 5%
B5: ★ Unit rates in column G are pre-filled where cost data exists in the source JSON. Amber cells = contractor to fill. Green cells = rate from data. Amount = Total Qty × Unit Rate.
B7: # | C7: Material ID | D7: Description / Specification | E7: Unit | F7: Total Qty | G7: Unit Rate (AED / unit) | H7: Amount (AED) | I7: Notes
B8: 1 | C8: 63982919-372c-48ff-ade1-eef50fd85f27 | D8: Timber | E8: M² | F8: =Materials_List!F8 | G8: 0 | H8: =IFERROR(F8*G8, "") | I8: Per m² supplied
B9: 2 | C9: d0256c18-4c77-4842-9e55-7c003d10bc7d | D9: Solid Wood | E9: M² | F9: =Materials_List!F9 | G9: 0 | H9: =IFERROR(F9*G9, "") | I9: Per m² supplied
B10: 3 | C10: 25480b7c-4cf5-4d27-a8bd-8367a66eed99 | D10: Wrapping Veneer WD002 | E10: M² | F10: =Materials_List!F10 | G10: 0 | H10: =IFERROR(F10*G10, "") | I10: Per m2 supplied
B11: 4 | C11: eed71fda-51a3-443f-ba35-fcf34da764b4 | D11: FR60mins Doorcore | E11: M² | F11: =Materials_List!F11 | G11: 0 | H11: =IFERROR(F11*G11, "") | I11: Per m² supplied
B12: 5 | C12: 4f50dbef-3b3d-4a36-996e-372a3728716d | D12: Solid Wood | E12: M² | F12: =Materials_List!F12 | G12: 0 | H12: =IFERROR(F12*G12, "") | I12: Per m supplied
B13: 6 | C13: a723fd95-ccea-465f-9f6a-1fbc1ab60d92 | D13: 12mmThk plain MDF | E13: M² | F13: =Materials_List!F13 | G13: 0 | H13: =IFERROR(F13*G13, "") | I13: Per m2 supplied
C15: SUBTOTAL (excl. VAT) | H15: =IFERROR(H8,0)+IFERROR(H9,0)+IFERROR(H10,0)+IFERROR(H11,0)+IFERROR(H12,0)+IFERROR(H13,0)
C16: VAT (5%) | H16: =H15*0.05
C17: GRAND TOTAL (incl. VAT) | H17: =H15+H16
B19: Rates to be provided by tendering contractor. All quantities are indicative and subject to field verification. Currency: AED · VAT @ 5%
